Workbook

Sheet Phase 2 Closure Summary
A1: PHASE 2 — CLOSED 2026-05-20
A2: All 11 similarity engines built · Both performance index gates passing · Test suite green · Ready for Phase 3
A4: Layer | B4: Status
A5: Similarity engines | B5: 11 / 11 built: pitcher (GMM W₂); batter/fielder/baserunner-advance/baserunner-steal/catcher v2/pitcher-steal/manager (RBF); situation (KDTree); pitch-to-pitch + batted-ball (FAISS)
A6: Database schema | B6: 12 Alembic migrations (0001 → 0012); 3 DuckDB migrations (0001 → 0003); 11 alembic + 3 duckdb chain integrity verified
A7: Performance index gates | B7: SIM-085 idx_pitches_situation: PASS against live 2024 staging. SIM-089 idx_pitches_pitcher_season_clean: PASS (6.77 ms / 50 ms budget)
A8: Test infrastructure | B8: 767 unit/integration tests passing, 22 skipped (env-dependent), 0 failed. Smoke tests green. Integration tests Docker-aware.
A9: Phase 3 architecture spec | B9: docs/architecture/2026-05-20-play-pool.md accepted: pre-filter contract, sub-index materialization, recency lifecycle, PlayPoolSampler API, performance budget
A10: Program audit | B10: Full 9-agent audit complete (docs/audit/2026-05-21-program-audit.md). 53 prioritized follow-up tickets filed (47 new + 6 pre-existing)
A11: Operator runbook | B11: WORKFLOW.md formatted for Windows cmd; covers ETL → DuckDB build → FastAPI serve → similarity API → smoke tests
A12: Operational issues resolved | B12: Postgres port conflict (host 5433 permanent via DB_HOST_PORT in .env); OneDrive sync truncation patterns documented; SIM-163 IS NOT DISTINCT FROM regression caught + fixed
A15: Sprint history
A16: Sprint | B16: Theme | C16: Tickets | D16: Disposition | E16: Outcome
A17: 2026-05-06 + 07 | B17: Data + Backend Stabilisation | C17: 16 (SIM-085/086/087/088/089/091/092/093/101/102/103/104/105/106/148/153) | D17: Closed 2026-05-07 | E17: 11 Alembic migrations baseline; backend live-pipeline hardened
A18: 2026-05-13 | B18: Phase 2 Closure & Engine Build-out | C18: 7 (SIM-072/073/041/042/157/158/159) | D18: Closed 2026-05-14 | E18: Catcher v2 (5 sub-scores); pitch-to-pitch + batted-ball FAISS engines; index acceptance harness
A19: 2026-05-20 | B19: Phase 2 hardening & Phase 3 kickoff | C19: 7 (SIM-051/160/162/149/150/300/161) | D19: Closed 2026-05-20 | E19: All Phase 2 engine unit tests; SIM-051 spray angle; Phase 3 spec accepted; live index runs PASS
A22: Phase 3 entry — Tier P0 tickets (next two sprints)
A23: Ticket | B23: Owner | C23: Size | D23: Why P0
A24: SIM-301 | B24: Backend Developer | C24: M | D24: Play-pool nightly cache serializer — first concrete Phase 3 deliverable. Materializes pre-filtered FAISS indexes onto disk for hot-load.
A25: SIM-302 | B25: Backend + ML Engineer | C25: M | D25: PlayPoolSampler API surface — how the sim loop will pull pitches/plays. Defines query contract for Phase 4.
A26: SIM-303 | B26: Backend Developer | C26: M | D26: Wire sampler into Phase 4 simulation-loop scaffold. Last Phase 3 ticket before Phase 4 implementation begins.
A27: SIM-220 | B27: ML Engineer | C27: L | D27: Backtesting framework — no simulator output is verifiable without this. Walk-forward + golden-file fixtures.
A28: SIM-201 | B28: Baseball Analyst | C28: L | D28: Manager decision logic spec — required for Step 7 of the sim loop. Probably needs its own sprint.
A29: SIM-202 | B29: Baseball Analyst | C29: S | D29: Centralize run-value constants in simulation/constants.py. Prerequisite for Phase 4 cleanup.
A30: SIM-118 | B30: Performance Engineer | C30: M | D30: pytest-benchmark harness — no measurable SLA without it. Engine query latency, GMM fit, sim loop stubs.
A31: SIM-280 | B31: Performance Engineer | C31: S | D31: Per-engine RAM budget within the 2 GB SIM-114 envelope. Required before play-pool cache is sized.
A32: SIM-281 | B32: Performance Engineer | C32: S | D32: ProcessPoolExecutor + shared-memory architecture decision. Locks the Phase 4 parallelism model.
A35: Open follow-ups from Phase 2 sprints
A36: Ticket | B36: Owner | C36: Size | D36: Description
A37: SIM-163 | B37: Performance Engineer | C37: S | D37: Re-verify SIM-085 latency on cold cache + consider INCLUDE columns on idx_pitches_situation for Index Only Scan (10x potential speedup).
A40: See docs/HANDOFF_PHASE3.md for the full Phase 3 onboarding doc.

Sheet Dashboard
B2: MLB Baseball Simulation Platform — Backlog Dashboard (Phase 3 COMPLETE)
B3: Generated 2026-05-21 — PHASE 3 COMPLETE; Phase-3-close program audit filed 41 Phase 4 tickets (SIM-220 + SIM-310..349). See docs/audit/2026-06-10-*.
B5: Tickets by Status | E5: Tickets by Priority (Open + Held)
B6: Status | C6: Count | E6: Priority | F6: Count
B7: Closed | C7: =COUNTIF('Full Backlog'!$H$2:$H$1000,"Closed") | E7: P0 | F7: =COUNTIFS('Full Backlog'!$E$2:$E$1000,"P0",'Full Backlog'!$H$2:$H$1000,"Open")+COUNTIFS('Full Backlog'!$E$2:$E$1000,"P0",'Full Backlog'!$H$2:$H$1000,"Held")
B8: Open | C8: =COUNTIF('Full Backlog'!$H$2:$H$1000,"Open") | E8: P1 | F8: =COUNTIFS('Full Backlog'!$E$2:$E$1000,"P1",'Full Backlog'!$H$2:$H$1000,"Open")+COUNTIFS('Full Backlog'!$E$2:$E$1000,"P1",'Full Backlog'!$H$2:$H$1000,"Held")
B9: Held | C9: =COUNTIF('Full Backlog'!$H$2:$H$1000,"Held") | E9: P2 | F9: =COUNTIFS('Full Backlog'!$E$2:$E$1000,"P2",'Full Backlog'!$H$2:$H$1000,"Open")+COUNTIFS('Full Backlog'!$E$2:$E$1000,"P2",'Full Backlog'!$H$2:$H$1000,"Held")
B10: In Progress | C10: =COUNTIF('Full Backlog'!$H$2:$H$1000,"In Progress") | E10: P3 | F10: =COUNTIFS('Full Backlog'!$E$2:$E$1000,"P3",'Full Backlog'!$H$2:$H$1000,"Open")+COUNTIFS('Full Backlog'!$E$2:$E$1000,"P3",'Full Backlog'!$H$2:$H$1000,"Held")
B11: Total | C11: =SUM(C7:C10)
B13: Open Tickets by Assignee Role | E13: Current Sprint (2026-06-10)
B14: Role | C14: Open | E14: Metric | F14: Value
B15: Data Engineer | C15: =SUMPRODUCT((ISNUMBER(SEARCH("Data Engineer",'Full Backlog'!$G$2:$G$1000)))*('Full Backlog'!$H$2:$H$1000="Open")) | E15: Total tickets | F15: =COUNTIF('Current Sprint'!A5:A100,"SIM-*")
B16: Backend Developer | C16: =SUMPRODUCT((ISNUMBER(SEARCH("Backend Developer",'Full Backlog'!$G$2:$G$1000)))*('Full Backlog'!$H$2:$H$1000="Open")) | E16: Open | F16: =COUNTIF('Current Sprint'!$H$2:$H$100,"Open")
B17: ML Engineer | C17: =SUMPRODUCT((ISNUMBER(SEARCH("ML Engineer",'Full Backlog'!$G$2:$G$1000)))*('Full Backlog'!$H$2:$H$1000="Open")) | E17: Closed | F17: =COUNTIF('Current Sprint'!$H$2:$H$100,"Closed")
B18: Baseball Analyst | C18: =SUMPRODUCT((ISNUMBER(SEARCH("Baseball Analyst",'Full Backlog'!$G$2:$G$1000)))*('Full Backlog'!$H$2:$H$1000="Open")) | E18: % Complete | F18: =IFERROR(F17/F15, 0)
B19: Performance Engineer | C19: =SUMPRODUCT((ISNUMBER(SEARCH("Performance Engineer",'Full Backlog'!$G$2:$G$1000)))*('Full Backlog'!$H$2:$H$1000="Open"))
B20: QA/DevOps | C20: =SUMPRODUCT((ISNUMBER(SEARCH("QA/DevOps",'Full Backlog'!$G$2:$G$1000)))*('Full Backlog'!$H$2:$H$1000="Open"))
B21: UX Designer | C21: =SUMPRODUCT((ISNUMBER(SEARCH("UX Designer",'Full Backlog'!$G$2:$G$1000)))*('Full Backlog'!$H$2:$H$1000="Open"))
B22: Betting Analyst | C22: =SUMPRODUCT((ISNUMBER(SEARCH("Betting Analyst",'Full Backlog'!$G$2:$G$1000)))*('Full Backlog'!$H$2:$H$1000="Open"))
B23: Product Manager | C23: =SUMPRODUCT((ISNUMBER(SEARCH("Product Manager",'Full Backlog'!$G$2:$G$1000)))*('Full Backlog'!$H$2:$H$1000="Open"))
B25: Quick Links
B26: Full Backlog | C26: Every ticket in the project
B27: Current Sprint | C27: Sprint 2026-06-10 Phase 3 completion commit list
B28: Phase 2 Completion | C28: Similarity engine suite + Phase 2 polish
B29: Phase 3 Gate | C29: Play pool architecture dependencies
B30: Phase 4 Gate | C30: Core simulation loop dependencies
B31: Phase 5 Gate | C31: Backend API + simulation runner
B32: Phase 6 Gate | C32: Frontend dependencies
B33: Phase 6 Build | C33: Frontend implementation tickets
B34: Phase 7 Gate | C34: Integration / testing / deployment
B36: Sprint 2026-05-13 — Phase 2 Closure & Engine Build-out (CLOSED 2026-05-14)
B37: Disposition: ✅ all 7 tickets accepted by PM on 2026-05-14
B38: • SIM-073 (DE) · steal_attempt_rate_against column + DuckDB migration 0002
B39: • SIM-072 (ML) · CatcherSimilarityEngine v2 — 5-sub-score split
B40: • SIM-157 (DE) · odds_hash backfill + Alembic 0012 (full unique)
B41: • SIM-158 (PE) · EXPLAIN ANALYZE harness (live run → SIM-161)
B42: • SIM-159 (BE) · MockOddsAPI vig flake fix (test-side bounds)
B43: • SIM-041 (ML) · Pitch-to-Pitch FAISS engine (Step 2.10)
B44: • SIM-042 (ML) · Batted-Ball FAISS engine (Step 2.11)
B45: All 11 similarity engines now built — Phase 2 milestone reached.
...

Sheet Current Sprint
A1: Sprint 2026-06-10 — CLOSED 2026-05-21: Phase 3 Completion — all 6 play-pool tickets shipped & accepted after independent QA (927 unit+regression passing / 1 skipped; 3 perf benches). Phase 3 (Play Pool Architecture) COMPLETE. See docs/SPRINT_2026-06-10_phase3_completion.md
A2: Sprint goal: ship the first Phase 3 deliverables — play-pool nightly cache (SIM-301) + sampler API (SIM-302) — alongside the Tier-P0 perf and BA prereqs that gate Phase 4. Backtesting framework (SIM-220) and manager decision logic spec (SIM-201) likely span two sprints; start scoping in this one.
A4: Ticket ID | B4: Title | C4: Category | D4: Type | E4: Priority | F4: Size | G4: Assignee Role | H4: Status | I4: Blocked | J4: Description | K4: Acceptance Criteria | L4: Dependencies | M4: Notes
A5: SIM-048 | B5: SimilarityEngineRegistry — unified interface for all 11 engines | C5: Phase 3 | D5: Feature | E5: P1 | F5: M | G5: ML Engineer | H5: Closed | I5: No | J5: Registry mapping canonical names to engine classes + metadata (family, score_type). | K5: similarity/registry.py; lists 11; lazy guarded imports; tests. | L5: SIM-071 | M5: Root of the Phase 3 remainder chain.
A6: SIM-076 | B6: recency_weight on sim pools + pool_build_metadata + walk-forward harness | C6: Phase 3 | D6: Improvement | E6: P1 | F6: L | G6: Data Engineer + ML Engineer | H6: Closed | I6: No | J6: 2x last-2-seasons recency weight, decay older; metadata table; harness. | K6: Migration 0004; schema v5; computor populates; harness module; tests. | L6: SIM-048 | M6: Recency boost materialized as a column.
A7: SIM-095 | B7: Incremental pitch_pool/outcome_pool rebuild | C7: Phase 3 | D7: Improvement | E7: P2 | F7: M | G7: Data Engineer | H7: Closed | I7: No | J7: Rebuild only seasons whose source changed; full rebuild fallback. | K7: _seasons_needing_rebuild; run() incremental=not full_rebuild; tests. | L7: SIM-076 | M7: Replaces nightly full delete+reinsert.
A8: SIM-111 | B8: Play-pool query API column contracts | C8: Phase 3 | D8: Gap | E8: P1 | F8: S | G8: Backend Developer + Data Engineer | H8: Closed | I8: No | J8: Document the 3 pools' query columns, pre-filter keys, access patterns, recency_weight. | K8: docs/architecture/2026-05-21-play-pool-query-contracts.md. | L8: SIM-076 | M8: Drove SIM-115 keep/drop decisions.
A9: SIM-115 | B9: Prune DuckDB sim pool indexes | C9: Phase 3 | D9: Improvement | E9: P1 | F9: S | G9: Data Engineer + Performance Engineer | H9: Closed | I9: No | J9: Keep query-path indexes; drop write-overhead ones (schema-qualified DROP). | K9: Migration 0005; schema updated; tests. | L9: SIM-111 | M9: DROP INDEX must be sim.-qualified.
A10: SIM-056 | B10: Count-stratified foul-ball frequency weighting design | C10: Phase 3 | D10: Design | E10: P2 | F10: S | G10: Baseball Analyst | H10: Closed | I10: No | J10: Count -> foul-frequency factor at outcome step; two-strike foul keeps PA alive. | K10: docs/architecture/2026-05-21-foul-ball-weighting.md + illustrative CSV. | L10: SIM-111 | M10: Design doc; impl in Phase 4 loop.

Sheet Full Backlog
A1: Ticket ID | B1: Title | C1: Category | D1: Type | E1: Priority | F1: Size | G1: Assignee Role | H1: Status | I1: Blocked | J1: Description/Problem Statement | K1: Acceptance Criteria | L1: Dependencies | M1: Notes/Rationale
A2: SIM-041 | B2: Build pitch-to-pitch similarity engine (2.10) — FAISS flat index | C2: Similarity Engines | D2: Feature | E2: P1 | F2: L (1–2 weeks) | G2: ML Engineer | H2: Shipped 2026-05-14 (sprint 2026-05-13) | I2: No | J2: Pitch-to-pitch similarity engine using FAISS flat index. Matches a query pitch (velocity, IVB, HB, spin rate, spin axis, release position, extension, plate location) to the most similar pitches in the pool. Powers the pitch selection step of the simulation loop (Phase 4 Step 2). | K2: 1. FAISS IVFFlat index with nlist=512, nprobe=64 (per SIM-114 spec — NOT flat index). 2. Mandatory pre-filter: filter pitch pool to same pitcher_id + batter_handedness before FAISS query (reduces search from 1M to ~3,000 rows). 3. Features: velo, ivb, hb, spin_rate, spin_axis, release_x, release_z, release_ext, plate_x, plate_z. 4. Returns top-k similar pitches with combined_weight (pitch_similarity × recency_weight). 5. Unit tests: identical pitches score 1.0; orthogonal pitch types score < 0.3; score symmetry; all scores in [0,1]. 6. Benchmark: single query on pre-filtered ~3,000 row pool < 0.15ms. | L2: SIM-071 (package structure), SIM-114 (FAISS design spec) | M2: Build order: this engine first (enables Phase 3 play pool testing).
A3: SIM-042 | B3: Build batted ball-to-batted ball similarity engine (2.11) — FAISS IVFFlat | C3: Similarity Engines | D3: Feature | E3: P1 | F3: L (1–2 weeks) | G3: ML Engineer | H3: Shipped 2026-05-14 (sprint 2026-05-13) | I3: No | J3: Batted ball similarity engine using FAISS IVFFlat index. Matches a query batted ball (exit velo, launch angle, pull_relative_spray_angle, bb_type) to similar historical batted balls for fielding resolution in the simulation loop. | K3: 1. FAISS IVFFlat index, same configuration as SIM-041. 2. Index on pull_relative_spray_angle (not raw spray_angle) — uses pre-computed column from sim.outcome_pool (SIM-051 prerequisite). 3. Features: exit_velo, launch_angle, pull_relative_spray_angle, bb_type (encoded). 4. Unit tests: same-direction HR vs opposite-field flyout score < 0.3; identical batted balls score 1.0; LHB pull and RHB pull with same exit velo/launch angle score >= 0.90. 5. Benchmark: single query < 0.15ms on pre-filtered pool. | L3: SIM-051 (pull_relative_spray_angle column must exist), SIM-041 (FAISS pattern) | M3: Required for fielding resolution in Phase 4 Step 4.
A4: SIM-043 | B4: Build catcher similarity engine (2.6) — requires schema columns, speed-adjusted CS rate | C4: Similarity Engines | D4: Feature | E4: P1 | F4: L (1–2 weeks) | G4: Data Engineer + ML Engineer | H4: Open | I4: No | J4: Catcher engine and the data layer work it requires. The current derived.catcher_season_metrics schema is missing all throwing-by-base columns. The speed-adjusted CS rate (required as the primary throwing feature) must be computed in the profile computor, not the engine. Three components: schema extension, computor implementation, and engine build. | K4: 1. DE: Add to derived.catcher_season_metrics: cs_attempts_2b/3b/home, cs_caught_2b/3b/home, cs_rate_2b/3b/home, speed_adjusted_cs_rate_2b/3b/home, pop_time_proxy, arm_strength_proxy. 2. DE: In _compute_catcher_throwing(): LEFT JOIN pg.raw.sprint_speed on runner_id for each SB attempt; compute expected_cs_rate from sprint speed distribution; store speed_adjusted_cs_rate = actual_cs_rate - expected_cs_rate. 3. MLE: Build catcher_similarity.py using speed_adjusted_cs_rate as primary throwing feature (not raw cs_rate), RBF kernel, EB shrinkage. 4. Integration: requires SIM-077 (sprint speed join) to be complete first. 5. Tests: catchers with elite pop times score highly with each other; catchers with poor blocking rates score < 0.3 with elite blockers. | L4: SIM-071, SIM-077 (sprint speed join in profile computor), SIM-084 | M4: Catcher throwing features feed into steal determination — Phase 4 Step 1.
A5: SIM-044 | B5: Build baserunner steal similarity engine (2.5) | C5: Similarity Engines | D5: Feature | E5: P1 | F5: M (3–5 days) | G5: ML Engineer | H5: Open | I5: No | J5: Separate from the extra-base advancement engine (already built), this engine scores baserunner-to-baserunner similarity specifically for stolen base decisions: sprint speed, historical SB attempt rate, success rate, and pickoff evasion. Powers Phase 4 Step 1 (steal determination). | K5: 1. RBF kernel, EB shrinkage, reliability weights matching other engine patterns. 2. Features: sprint_speed, sb_attempt_rate, sb_success_rate, cs_rate. 3. Sprint speed sourced from raw.sprint_speed (measured) with proxy fallback. 4. Profiles with below_minimum_sample MUST load (apply EB shrinkage, do not exclude). 5. Unit tests: fast runners with high success rate score highly together; slow runners with low attempt rate score < 0.3 with fast runners. 6. query() returns results for a rookie with only 3 SB attempts (EB shrinkage). | L5: SIM-071, SIM-070 (below_minimum_sample fix), SIM-077 (sprint speed) | M5: Distinct from baserunner extra-base engine — steal-specific features and use case.
A6: SIM-045 | B6: Build pitcher-allowing-steals similarity engine (2.7) | C6: Similarity Engines | D6: Feature | E6: P1 | F6: M (3–5 days) | G6: ML Engineer | H6: Open | I6: No | J6: Pitcher-to-pitcher similarity specifically for stolen base context: how similar is this pitcher's delivery to others in terms of allowing baserunners to run? Features: stretch timing, slide step usage, pickoff attempt rate, pickoff success rate, historical SB attempts allowed per runner opportunity. | K6: 1. Features as per SIM-059 revised spec: stretch_time, slide_step_rate, pickoff_attempt_rate, pickoff_success_rate, sb_attempts_allowed_per_opp. 2. RBF kernel with EB shrinkage. Minimum sample threshold: 50 runner opportunities. 3. Separate handedness partitions (LHP/RHP have different pickoff mechanics). 4. Unit tests: pitchers known for quick deliveries score highly together; deliberate delivery pitchers cluster separately. | L6: SIM-071, SIM-059 (revised feature set spec) | M6: Feed into Phase 4 Step 1 steal attempt probability.
A7: SIM-046 | B7: Build manager similarity engine (2.8) | C7: Similarity Engines | D7: Feature | E7: P1 | F7: M (3–5 days) | G7: ML Engineer + Data Engineer | H7: Open | I7: No | J7: Manager-to-manager similarity for substitution decision patterns. Requires SIM-057 manager schema additions (opener_rate, extreme_shift_rate, IBB rate) to be implemented in the profile computor first. The engine then scores managers on their tendencies for: bullpen usage, pinch hitting, position player usage in leverage situations. | K7: 1. Depends on SIM-057: opener_rate, extreme_shift_rate, intentional_walk_rate columns populated (not NULL) in derived.manager_season_metrics. 2. Features: quick_hook_rate, opener_rate, extreme_shift_rate, intentional_walk_rate, sp_pitch_count_mean, bullpen_leverage_mapping. 3. RBF kernel, EB shrinkage (EB_N_PRIOR appropriate for manager-level stats which stabilize in ~1 full season). 4. Unit tests: aggressive bullpen managers (low quick_hook) cluster together; old-school managers cluster separately from analytics-driven ones. | L7: SIM-071, SIM-057 (manager schema additions) | M7: Manager engine powers Phase 4 Step 7 (manager decision logic).
A8: SIM-047 | B8: Build situation-to-situation similarity engine (2.9) — KDTree | C8: Similarity Engines | D8: Feature | E8: P1 | F8: M (3–5 days) | G8: ML Engineer | H8: Open | I8: No | J8: Situation similarity engine using KDTree (small feature space, no FAISS needed). Features: count (balls, strikes), outs, runners_state (bitmask 0-7), score_diff (capped ±5), inning, leverage_index. Returns similar historical situations as a cross-cutting weight modifier applied to other engines' scores. | K8: 1. scikit-learn BallTree or KDTree. Euclidean metric on normalized features. 2. Features: balls, strikes, outs, runners_state (bitmask normalized 0-1), score_diff (capped ±5, normalized), inning (normalized 1-9+), leverage_index. 3. Z-score normalization with EB shrinkage toward mean situation. 4. Unit tests: tie game 9th inning bases loaded 2 outs scores highly with similar high-leverage situations; 1st inning 0-0 scores poorly against 9th inning scenarios. 5. Requires SIM-085 (situation composite index) for efficient DB queries. | L8: SIM-071, SIM-085 (situation index), SIM-058 (LI lookup table for features) | M8: Cross-cutting weight modifier — used to adjust all other engine weights by game situation.
A9: SIM-048 | B9: Build SimilarityEngineRegistry — unified interface for all 11 engines | C9: Similarity Engines | D9: Feature | E9: P1 | F9: M (3–5 days) | G9: ML Engineer + Backend Developer | H9: Closed | I9: No | J9: The SimilarityEngineRegistry provides a single interface for the simulation loop to query any of the 11 engines. It handles: engine initialization and build() orchestration, the SimilarityEngine Protocol from base.py, engine selection by type, and results caching. Required before Phase 3 can begin. | K9: 1. registry.py in similarity/: SimilarityEngineRegistry class with methods get_pitcher_engine(), get_batter_engine(), get_fielder_engine(), etc. 2. All engines import from similarity.base (SIM-071 prerequisite). 3. Registry build(): orchestrates all 11 engine build() calls in dependency order. 4. Registry supports SIM-081 (save/load): registry.save_all(dir), registry.load_all(dir) convenience methods. 5. Unit tests: registry.get_pitcher_engine() returns a PitcherSimilarityEngine instance; querying a non-existent engine raises ValueError with clear message. | L9: SIM-071 (package structure + base.py), all 11 engines complete | M9: Phase 2 completion gate — registry is the final deliverable.
A10: SIM-050 | B10: Merge fielder diagnostics into similarity_diagnostics.py — fix silent CI failure | C10: Similarity Engines | D10: Bug | E10: P1 | F10: S (< 1 day) | G10: ML Engineer | H10: Open | I10: No | J10: Fielder diagnostics live in fielder_diagnostics_ext.py and are not called from the shared CLI. Running 'python similarity_diagnostics.py' produces exit code 0 even with a broken fielder engine. total_flags is computed without fielder flags, silently passing any CI check that calls this script. | K10: 1. Merge fielder_diagnostics_ext.py content into similarity_diagnostics.py. 2. Wire fielder_report.n_flags into total_flags in the CLI main block. 3. Verify: 'python similarity_diagnostics.py' returns exit code 1 when the fielder engine has flags. 4. Prerequisite for SIM-154 (model regression CI gate) to cover all engines. | L10: None | M10: CI regression gate (SIM-154) is incomplete until this is fixed.
A11: SIM-051 | B11: Pre-compute pull_relative_spray_angle in sim.outcome_pool at ETL time | C11: Schema / ETL | D11: Improvement | E11: P1 | F11: S (1–2 days) | G11: Data Engineer | H11: Closed | I11: No | J11: Raw spray_angle is directionally biased by batter handedness. LHB pull doubles and RHB pull doubles are physically similar but have opposite spray angle signs. The FAISS batted ball engine must index on pull-relative spray angle. This must be pre-computed at ETL time, not transformed at query time for every lookup. | K11: 1. Add pull_relative_spray_angle FLOAT column to sim.outcome_pool (DuckDB migration). 2. Populate in _build_outcome_pool(): CASE WHEN stand='R' THEN spray_angle WHEN stand='L' THEN -spray_angle ELSE CASE WHEN bat_hand='R' THEN spray_angle ELSE -spray_angle END END. 3. Use bat_hand column for switch hitters (records actual handedness on that pitch). 4. Unit test: LHB pull double and RHB pull double with identical exit_velo/launch_angle should have pull_relative_spray_angle values within 5 degrees of each other. | L11: SIM-084 (DuckDB migration pattern via Alembic/DuckDB versioning) | M11: Blocks SIM-042. Must land before the batted ball FAISS index is built.
A12: SIM-052 | B12: Add pitch-archetype pre-filter to pitcher similarity engine | C12: Similarity Engines | D12: Improvement | E12: P2 | F12: S (1–2 days) | G12: ML Engineer + Baseball Analyst | H12: Open | I12: No | J12: Pitch-to-pitch similarity queries should be optionally pre-filtered to the same pitch archetype (e.g., don't compare a sweeper to a sinker) before FAISS search. This reduces noise in the pitch selection pool for pitchers with very distinct pitch types and improves the relevance of top-k results. | K12: 1. Add optional pitch_archetype_filter parameter to pitch-to-pitch engine query(). 2. Archetype derived from GMM component labels (display_label from profile computor). 3. When filter is applied, only search within the pre-filtered subset. 4. When filter is None, full pool search (backward compatible). 5. Baseball Analyst validates that archetype groupings make baseball sense. 6. Unit test: querying a 4-seam fastball with archetype filter returns only fastball-type results. | L12: SIM-041 (pitch-to-pitch engine must exist first) | M12: Improvement to pitch selection quality — optional filter, not required for correctness.
... A151: SIM-349 | B151: Situational-decision module (IBB/sac/hit-and-run/shift) | C151: Phase 4 | D151: Design | E151: P3 | F151: M (3–5 days) | G151: Baseball Analyst | H151: Open | I151: Yes | J151: Situational-decision module (IBB/sac/hit-and-run/shift) | K151: See docs/audit/2026-06-10-phase4-prioritized-tickets.md | L151: SIM-323 | M151: Triggers for count/leverage-driven events.
A152: SIM-350 | B152: API response-serialization contract — Pydantic models + array-safe JSON for GameSimSummary/WinProbability/snapshots/PMFs/EdgeReport | C152: Phase 5 — Backend API | D152: Spec | E152: P0 | F152: M | G152: Backend Developer · UX Designer | H152: Closed | I152: No | J152: Numpy-bearing output dataclasses had no JSON contract. | K152: api/serialization.py + api/schemas.py; model_dump_json round-trips with no numpy leak. | M152: Closed 2026-05-24 (Sprint 1). 21 tests.
A153: SIM-351 | B153: Auth + rate-limit + CORS baseline | C153: Phase 5 — Backend API | D153: Feature | E153: P0 | F153: M | G153: Backend Developer · QA/DevOps | H153: Closed | I153: No | J153: No auth/rate-limit anywhere; CORS was ['*']. | K153: api/auth.py: API-key dep + stdlib rate limiter + env CORS. | M153: Closed 2026-05-24 (Sprint 1). 9 tests.
A154: SIM-352 | B154: Production DB-backed machine_factory for BatchRunner (real sims over PlayPoolSampler + SIM-333 tiles) | C154: Phase 5 — Backend API | D154: Feature | E154: P0 | F154: L | G154: Backend Developer · Performance Engineer · ML Engineer | H154: Closed | I154: No | J154: Only the no-DB rng factory existed; /simulate couldn't run a real game. | K154: simulation/production_factory.py; injectable builders for no-DB tests. | M154: Closed 2026-05-24 (Sprint 1). 13 tests. Live-DB SLA acceptance → SIM-372.
A155: SIM-353 | B155: Runtime lineup/substitution resolver: Postgres raw.game_lineups → GameState (the SIM-338 gap) | C155: Phase 5 — Backend API | D155: Feature | E155: P0 | F155: L | G155: Data Engineer · Backend Developer | H155: Closed | I155: No | J155: No runtime read path from lineup stores to GameState. | K155: simulation/lineup_resolver.py; subs by sequence + as_of_at_bat. | M155: Closed 2026-05-24 (Sprint 1). 24 tests. raw.game_lineups already in migration 0001.
A156: SIM-354 | B156: API skeleton — mount ws_router/odds_router/live pipeline into api/main.py | C156: Phase 5 — Backend API | D156: Gap | E156: P0 | F156: S | G156: Backend Developer · Data Engineer | H156: Closed | I156: No | J156: Built routers/pipeline never mounted into the app. | K156: api/main.py mounts routers; pipeline gated by LIVE_PIPELINE_ENABLED. | M156: Closed 2026-05-24 (Sprint 1). 11 tests.
A157: SIM-355 | B157: GET /api/games/{date} + GET /{game_pk}/simulate (100-iteration runner → GameSimSummary) | C157: Phase 5 — Backend API | D157: Feature | E157: P1 | F157: L | G157: Backend Developer | H157: Closed | I157: No | J157: The core endpoints. | M157: SIM-350, SIM-352, SIM-353 | Closed 2026-05-24 (Phase 5 Sprint 2).
A158: SIM-356 | B158: Sim-result + pitch-snapshot persistence (Alembic 0014 / DuckDB v8) backing /state + /plays | C158: Phase 5 — Backend API | D158: Feature | E158: P1 | F158: M | G158: Data Engineer | H158: Closed | I158: No | J158: Only an ephemeral Redis/JSONB blob today. | M158: SIM-350 | Closed 2026-05-24 (Phase 5 Sprint 2).
A159: SIM-357 | B159: GET /{game_pk}/plays + GET /{game_pk}/state/{at_bat}/{pitch} (from persisted snapshots) | C159: Phase 5 — Backend API | D159: Feature | E159: P1 | F159: M | G159: Backend Developer | H159: Closed | I159: No | M159: SIM-356 | Closed 2026-05-24 (Phase 5 Sprint 2).
A160: SIM-358 | B160: POST /{game_pk}/simulate/with_override (roster-mod re-sim → OverrideDelta) | C160: Phase 5 — Backend API | D160: Feature | E160: P1 | F160: M | G160: Backend Developer | H160: Closed | I160: No | M160: SIM-355 | Closed 2026-05-24 (Phase 5 Sprint 2).
A161: SIM-359 | B161: Redis TTL wiring for the API (sim 60s / pool 5-min / odds 5-min) | C161: Phase 5 — Backend API | D161: Feature | E161: P1 | F161: S | G161: Backend Developer | H161: Closed | I161: No | J161: Constants exist; not wired to the API. | M161: SIM-355 | Closed 2026-05-24 (Phase 5 Sprint 2).
A162: SIM-360 | B162: Persistent ProcessPool + shared-memory lifecycle for the long-lived API | C162: Phase 5 — Backend API | D162: Perf | E162: P1 | F162: M | G162: Performance Engineer | H162: Open | I162: No | J162: Today a fresh pool + shm publish/unlink per request. | M162: SIM-352
A163: SIM-361 | B163: CalibrationReport JSON persistence + API-startup load + CalibrationMap wiring; build all 11 engines | C163: Phase 5 — Backend API | D163: Feature | E163: P1 | F163: M | G163: ML Engineer | H163: Open | I163: No | J163: Only the pitcher engine builds at startup today.
A164: SIM-362 | B164: Per-inning linescore + team R/H/E tracking in the loop | C164: Phase 5 — Loop Outputs | D164: Gap | E164: P2 | F164: L | G164: Backend Developer · Baseball Analyst | H164: Open | I164: No | J164: Only cumulative score exists; LinescoreGraphic unservable.
A165: SIM-363 | B165: Per-position fielder tracking → populate FieldSnapshot's 9 defensive slots | C165: Phase 5 — Loop Outputs | D165: Gap | E165: P2 | F165: M | G165: Backend Developer · ML Engineer | H165: Open | I165: No | J165: FieldSnapshot slots empty today. | M165: SIM-353
A166: SIM-364 | B166: Winning / losing / save pitcher attribution | C166: Phase 5 — Loop Outputs | D166: Gap | E166: P2 | F166: M | G166: Baseball Analyst · Backend Developer | H166: Open | I166: No | J166: Required by the Completed game card; absent today. | M166: SIM-362
A167: SIM-365 | B167: Extend PlayerStatLine (2B/3B/R/SB; pitcher hits/runs-allowed) + fix SIM-329 prop-TB lower bound | C167: Phase 5 — Loop Outputs | D167: Improvement | E167: P2 | F167: M | G167: Baseball Analyst · Backend Developer | H167: Open | I167: No | J167: prop TB is a lower bound (h+3·hr) until 2B/3B tracked.
A168: SIM-366 | B168: Per-player 100-iteration boxscore-average API shape (PropDistributionSet means) | C168: Phase 5 — Backend API | D168: Feature | E168: P2 | F168: S | G168: Backend Developer · UX Designer | H168: Open | I168: No | M168: SIM-350
A169: SIM-367 | B169: Run-line / spread EdgeReport from raw score-margin arrays | C169: Phase 5 — Betting | D169: Gap | E169: P2 | F169: S | G169: Betting Analyst · ML Engineer | H169: Open | I169: No | J169: Only ML/total/prop edge exist.
A170: SIM-368 | B170: CLV / line-movement time-series surface (opening→closing) | C170: Phase 5 — Betting | D170: Gap | E170: P2 | F170: M | G170: Betting Analyst · Data Engineer | H170: Open | I170: No | J170: CLV is a single entry-vs-close snapshot today. | M170: SIM-370
A171: SIM-369 | B171: Bet-signal / +EV recommendation endpoint contract | C171: Phase 5 — Betting | D171: Feature | E171: P2 | F171: M | G171: Betting Analyst | H171: Open | I171: No | J171: Aggregate EdgeReports into a fireable signal. | M171: SIM-367
A172: SIM-370 | B172: Real odds/prop provider swap behind MockOddsAPI | C172: Phase 5 — Betting | D172: Feature | E172: P2 | F172: M | G172: Data Engineer · Betting Analyst | H172: Open | I172: No | J172: Multi-book, sharp flag; cadence wired by SIM-340.
A173: SIM-371 | B173: API integration + WebSocket + historical-replay E2E suite | C173: Phase 5 — Testing | D173: Test | E173: P2 | F173: L | G173: QA/DevOps · Baseball Analyst | H173: Open | I173: No | J173: api/websocket/ is an empty placeholder. | M173: SIM-355
A174: SIM-372 | B174: End-to-end /simulate latency perf gate (2s/30s SLA) | C174: Phase 5 — Testing | D174: Perf | E174: P2 | F174: M | G174: Performance Engineer | H174: Open | I174: No | J174: Current bench skips the request path. | M174: SIM-352
A175: SIM-373 | B175: nginx reverse proxy w/ WebSocket upgrade + dev/staging/prod env configs | C175: Phase 5 — Infra | D175: Infra | E175: P3 | F175: M | G175: QA/DevOps | H175: Open | I175: No | M175: SIM-354
A176: SIM-374 | B176: Prometheus + Grafana monitoring (sim latency, API p95, pipeline freshness) | C176: Phase 5 — Infra | D176: Infra | E176: P3 | F176: M | G176: QA/DevOps | H176: Open | I176: No | M176: SIM-373
A177: SIM-375 | B177: Fix docker-compose.yml to mount ./simulation + remove the dead simulator/ package | C177: Phase 5 — Infra | D177: Bug | E177: P3 | F177: S | G177: Data Engineer · QA/DevOps | H177: Closed | I177: No | J177: Compose mounted the empty ./simulator stub. | K177: compose mounts ./simulation; Dockerfile copies simulation/+betting/; simulator/ deleted. | M177: Closed 2026-05-24 (Sprint 1).
A178: SIM-376 | B178: Add api/ to the coverage gate (pyproject source + ci --cov=api) | C178: Phase 5 — Infra | D178: Bug | E178: P3 | F178: S | G178: QA/DevOps | H178: Closed | I178: No | J178: Only the Makefile measured api/ coverage. | K178: pyproject source += api; ci --cov=api. | M178: Closed 2026-05-24 (Sprint 1).
...

Sheet Phase 2 Completion
A1: Ticket ID | B1: Title | C1: Category | D1: Type | E1: Priority | F1: Size | G1: Assignee Role | H1: Status | I1: Blocked | J1: Description/Problem Statement | K1: Acceptance Criteria | L1: Dependencies | M1: Notes/Rationale
A2: SIM-051 | B2: Pre-compute pull_relative_spray_angle in sim.outcome_pool at ETL time | C2: Schema / ETL | D2: Improvement | E2: P1 | F2: S (1–2 days) | G2: Data Engineer | H2: Closed | I2: No | J2: Raw spray_angle is directionally biased by batter handedness. LHB pull doubles and RHB pull doubles are physically similar but have opposite spray angle signs. The FAISS batted ball engine must index on pull-relative spray angle. This must be pre-computed at ETL time, not transformed at query time for every lookup. | K2: 1. Add pull_relative_spray_angle FLOAT column to sim.outcome_pool (DuckDB migration). 2. Populate in _build_outcome_pool(): CASE WHEN stand='R' THEN spray_angle WHEN stand='L' THEN -spray_angle ELSE CASE WHEN bat_hand='R' THEN spray_angle ELSE -spray_angle END END. 3. Use bat_hand column for switch hitters (records actual handedness on that pitch). 4. Unit test: LHB pull double and RHB pull double with identical exit_velo/launch_angle should have pull_relative_spray_angle values within 5 degrees of each other. | L2: SIM-084 (DuckDB migration pattern via Alembic/DuckDB versioning) | M2: Blocks SIM-042. Must land before the batted ball FAISS index is built.
A3: SIM-063 | B3: Add effective_date and prior_seasons_factor to park_factors — extended with DE schema work | C3: Schema / ETL | D3: Feature | E3: P1 | F3: M (3–5 days) | G3: Data Engineer | H3: Open | I3: No | J3: Current park_factors PRIMARY KEY (venue_id, season, factor_type) prevents representing mid-season park renovations and early-season thin samples. DuckDB requires a CREATE-INSERT-DROP-RENAME pattern to ALTER PRIMARY KEY since ALTER TABLE ADD PRIMARY KEY is unsupported. | K3: 1. Alter PRIMARY KEY to (venue_id, season, factor_type, effective_date). DuckDB implementation: CREATE new table with correct PK → INSERT SELECT from old → DROP old → RENAME new. 2. Add effective_date DATE NOT NULL DEFAULT '2000-01-01' (full-season baseline). 3. Add prior_seasons_factor FLOAT: weighted average of regressed_factor across prior 3 seasons for same venue/factor_type. Computed in _compute_park_factors(). 4. Deliver as numbered DuckDB migration file. 5. Sequence: SIM-063 first (PRIMARY KEY change), then SIM-094 (adds directional HR distance columns). | L3: SIM-084 (DuckDB migration versioning) | M3: Must complete before SIM-094 (directional HR distances) — both modify park_factors; PK change first.
A4: SIM-074 | B4: Fix barrel_rate computation — implement full Statcast sliding-scale definition | C4: Schema / ETL | D4: Bug | E4: P1 | F4: S (1–2 days) | G4: Data Engineer | H4: Closed | I4: No | J4: The current barrel definition (exit_velo >= 98 AND launch_angle 26-30 degrees) uses a tight fixed band. Statcast's actual barrel definition is a sliding scale: required LA decreases as EV increases above 98 mph. This produces barrel rates substantially lower than published Statcast values, biasing power profiles. | K4: 1. Replace fixed-band definition with sliding-scale lookup table: at 98 mph LA must be 26-30°; at 100 mph 24-33°; at 110 mph 17-41°; at 116+ mph 8-50°. Implement as linear interpolation between anchor points. 2. Verify: recalculate barrel_rate for 10 known players (e.g., Aaron Judge, Shohei Ohtani) and confirm within 0.5% of published Baseball Savant barrel rates. 3. Update avg_launch_angle computation (suspected NULL gap) — confirm it is populated in derived.batter_season_metrics. 4. Re-run batter profile computor; confirm barrel_rate column no longer systematically lower than Savant leaderboard. | L4: None | M4: Affects power sub-score and HR prop calibration. Also confirms avg_launch_angle is populated.
A5: SIM-077 | B5: Join raw.sprint_speed into baserunner and fielder profile computations — replace proxy and hardcoded defaults | C5: Schema / ETL | D5: Bug | E5: P1 | F5: S (1–2 days) | G5: Data Engineer | H5: Open | I5: No | J5: raw.sprint_speed exists and is populated by etl_sprint_speed_loader.py, but is never joined in any profile computation. The baserunner profile computor uses an inverted proxy formula (measures outcome success, not speed). The fielder computor uses DEFAULT_SPRINT_SPEED_FPS=27.0 (one speed for every batter in the league). Both are wrong and the fix data exists in the database. | K5: 1. In _compute_baserunner_profiles(): LEFT JOIN pg.raw.sprint_speed ss ON ss.player_id = runner_id AND ss.season. Use ss.sprint_speed as the primary value, NULL fallback (not the proxy formula). Track sprint_speed_source='measured'|'null'. 2. In _compute_infield_oaa() and _compute_outfield_catch_probability(): LEFT JOIN pg.raw.sprint_speed for batter sprint speeds; replace DEFAULT_SPRINT_SPEED_FPS=27.0. 3. Assertion: sprint_speed_source='measured' coverage > 80% for 2022-2025 seasons. 4. Unit test: a profile using measured sprint_speed differs in Speed sub-score from one using the proxy formula. | L5: etl_sprint_speed_loader.py must have been run for 2022-2025 | M5: The sprint speed table was built specifically to fix this — it's just not wired in yet.
A6: SIM-090 | B6: Replace per-game psycopg2 connect/close with connection pool in ETL | C6: Schema / ETL | D6: Improvement | E6: P1 | F6: M (3–5 days) | G6: Data Engineer | H6: Closed | I6: No | J6: Each call to _get_conn() opens and closes a new psycopg2.connect() connection. For a full-season backfill of ~2,400 games, this is 2,400 sequential connection handshakes adding 24-120 seconds of pure TCP overhead. The freshness upsert adds a second open/close per game. | K6: 1. Replace with psycopg2.pool.ThreadedConnectionPool(minconn=2, maxconn=10) initialized in HistoricalDataLoader.__init__(). 2. Refactor _get_conn() context manager to acquire from pool and release on exit. 3. Pass a single connection through _process_and_insert() and _log_freshness() to eliminate the double open/close per game. 4. For Phase 5 async compatibility: note that asyncpg should replace psycopg2 throughout the ETL during Phase 5 migration — keep as psycopg2 pool for now. 5. Benchmark: full-season backfill completes at least 20% faster. | L6: None | M6: Deferred from current sprint — useful but not blocking Phase 2 completion.
A7: SIM-095 | B7: Implement incremental pitch_pool and outcome_pool rebuild — replace nightly full delete+reinsert | C7: Schema / ETL | D7: Improvement | E7: P2 | F7: M (3–5 days) | G7: Data Engineer | H7: Closed | I7: No | J7: Nightly full pool rebuild deletes and re-inserts ~700K rows (current season). For a 4-season data set this is 2.8M+ rows, taking ~10 minutes nightly. The incremental path only inserts new rows where game_date > last_built, reducing nightly cost to ~30 seconds. | K7: 1. Add sim.pool_build_metadata table: key VARCHAR PK, value TEXT, updated_at TIMESTAMPTZ. 2. Track last_built_game_date per pool (pitch_pool, outcome_pool, stolen_base_pool). 3. When full_rebuild=False: INSERT only rows with game_date > last_built_game_date; update last_built_game_date on success. 4. Full rebuild path (full_rebuild=True) unchanged. 5. Apply same incremental logic to _build_outcome_pool() and _build_stolen_base_pool(). 6. Benchmark: nightly incremental for current season only < 60 seconds. | L7: SIM-076 (pool_build_metadata table shared for recency weight tracking) | M7: Operational necessity once historical data grows — without this, nightly batch becomes untenable.
A8: SIM-097 | B8: Fix manager concurrent replacement race condition — add SELECT FOR UPDATE row lock | C8: Schema / ETL | D8: Bug | E8: P2 | F8: S (< 1 day) | G8: Data Engineer | H8: Open | I8: No | J8: In _ensure_managers(), when a new manager is detected, the code issues UPDATE (set season_end on old manager) then INSERT (new manager). Two concurrent workers processing games in parallel may both see the 'manager missing' state and both attempt the UPDATE + INSERT — producing a duplicate key violation or incorrect season_end date. | K8: 1. Wrap UPDATE + INSERT in a single transaction with SELECT ... FOR UPDATE on the existing manager row before updating. 2. The FOR UPDATE lock ensures only one worker proceeds with the manager change. 3. Unit test: simulate two concurrent workers detecting the same missing manager; assert only one manager row is inserted and no duplicate key error occurs. 4. Only relevant for parallel season backfills — serial loads are unaffected. | L8: None | M8: Low urgency until parallel backfill is implemented. Deferred to Phase 5 async migration.
A9: SIM-098 | B9: Implement pipeline observability baseline: raw.pipeline_run_log, freshness staleness alert, Prometheus counters | C9: Infrastructure | D9: Gap | E9: P1 | F9: M (3–5 days) | G9: Data Engineer | H9: Open | I9: No | J9: No monitoring infrastructure exists for the data pipeline. A nightly profile computor failure would not alert anyone. For a production betting platform with time-sensitive data freshness requirements, silent failures are unacceptable. | K9: 1. Add raw.pipeline_run_log table: id, pipeline_name, started_at, finished_at, rows_inserted, rows_failed, exit_status CHECK ('success','partial','failed'), error_summary TEXT. Insert at start, update on completion/failure in all pipeline scripts. 2. Staleness check: daily scheduled query raises log.warning if MAX(last_date) in raw.etl_data_freshness is > 2 days old. 3. Prometheus counters in player_profile_computor.py: rows_processed_total (counter), profile_compute_duration_seconds (histogram per step), below_minimum_sample_count (gauge per entity type). 4. Full Grafana dashboard deferred to Phase 7; instrumentation hooks must exist in Phase 5 so the dashboard has data to display. 5. Alembic migration for raw.pipeline_run_log. | L9: SIM-084 (Alembic) | M9: Instrumentation hooks must exist in Phase 5 — retrofitting monitoring after Phase 7 deploy is too late.
A10: SIM-041 | B10: Build pitch-to-pitch similarity engine (2.10) — FAISS flat index | C10: Similarity Engines | D10: Feature | E10: P1 | F10: L (1–2 weeks) | G10: ML Engineer | H10: Shipped 2026-05-14 (sprint 2026-05-13) | I10: No | J10: Pitch-to-pitch similarity engine using FAISS flat index. Matches a query pitch (velocity, IVB, HB, spin rate, spin axis, release position, extension, plate location) to the most similar pitches in the pool. Powers the pitch selection step of the simulation loop (Phase 4 Step 2). | K10: 1. FAISS IVFFlat index with nlist=512, nprobe=64 (per SIM-114 spec — NOT flat index). 2. Mandatory pre-filter: filter pitch pool to same pitcher_id + batter_handedness before FAISS query (reduces search from 1M to ~3,000 rows). 3. Features: velo, ivb, hb, spin_rate, spin_axis, release_x, release_z, release_ext, plate_x, plate_z. 4. Returns top-k similar pitches with combined_weight (pitch_similarity × recency_weight). 5. Unit tests: identical pitches score 1.0; orthogonal pitch types score < 0.3; score symmetry; all scores in [0,1]. 6. Benchmark: single query on pre-filtered ~3,000 row pool < 0.15ms. | L10: SIM-071 (package structure), SIM-114 (FAISS design spec) | M10: Build order: this engine first (enables Phase 3 play pool testing).
A11: SIM-042 | B11: Build batted ball-to-batted ball similarity engine (2.11) — FAISS IVFFlat | C11: Similarity Engines | D11: Feature | E11: P1 | F11: L (1–2 weeks) | G11: ML Engineer | H11: Shipped 2026-05-14 (sprint 2026-05-13) | I11: No | J11: Batted ball similarity engine using FAISS IVFFlat index. Matches a query batted ball (exit velo, launch angle, pull_relative_spray_angle, bb_type) to similar historical batted balls for fielding resolution in the simulation loop. | K11: 1. FAISS IVFFlat index, same configuration as SIM-041. 2. Index on pull_relative_spray_angle (not raw spray_angle) — uses pre-computed column from sim.outcome_pool (SIM-051 prerequisite). 3. Features: exit_velo, launch_angle, pull_relative_spray_angle, bb_type (encoded). 4. Unit tests: same-direction HR vs opposite-field flyout score < 0.3; identical batted balls score 1.0; LHB pull and RHB pull with same exit velo/launch angle score >= 0.90. 5. Benchmark: single query < 0.15ms on pre-filtered pool. | L11: SIM-051 (pull_relative_spray_angle column must exist), SIM-041 (FAISS pattern) | M11: Required for fielding resolution in Phase 4 Step 4.
A12: SIM-044 | B12: Build baserunner steal similarity engine (2.5) | C12: Similarity Engines | D12: Feature | E12: P1 | F12: M (3–5 days) | G12: ML Engineer | H12: Open | I12: No | J12: Separate from the extra-base advancement engine (already built), this engine scores baserunner-to-baserunner similarity specifically for stolen base decisions: sprint speed, historical SB attempt rate, success rate, and pickoff evasion. Powers Phase 4 Step 1 (steal determination). | K12: 1. RBF kernel, EB shrinkage, reliability weights matching other engine patterns. 2. Features: sprint_speed, sb_attempt_rate, sb_success_rate, cs_rate. 3. Sprint speed sourced from raw.sprint_speed (measured) with proxy fallback. 4. Profiles with below_minimum_sample MUST load (apply EB shrinkage, do not exclude). 5. Unit tests: fast runners with high success rate score highly together; slow runners with low attempt rate score < 0.3 with fast runners. 6. query() returns results for a rookie with only 3 SB attempts (EB shrinkage). | L12: SIM-071, SIM-070 (below_minimum_sample fix), SIM-077 (sprint speed) | M12: Distinct from baserunner extra-base engine — steal-specific features and use case.
... A61: SIM-159 | B61: Tighten SIM-132 vig RNG so moneyline boundary test is no longer flaky | C61: Live Pipeline | D61: Bug | E61: P1 | F61: S (<1 day) | G61: Backend Developer | H61: Shipped 2026-05-14 (sprint 2026-05-13) | I61: No | J61: MockOddsAPI samples vig from rng.uniform(0.06, 0.10). Overround = 1 + vig/2 ∈ [1.030, 1.050]. Regression test asserts strict > 1.03; for game_pk=12345 the inflation path produces 1.0286. | K61: 1. EITHER tighten RNG floor to rng.uniform(0.07, 0.10), OR weaken the assertion to >= 1.03 - 1e-9 with an upper bound < 1.05 + 1e-9. PM prefers the test-side change to keep the SIM-132 mock consistent with real sharp-book MLB data. 2. The [12345] parametrized case passes deterministically across 100 runs. 3. Calibration choice documented in test file. | L61: SIM-132 (already shipped) | M61: Created 2026-05-08 from PM acceptance review. Renumbered from SIM-096 to avoid collision with the existing async-models ticket.

Sheet Phase 3 Gate
A1: Ticket ID | B1: Title | C1: Category | D1: Type | E1: Priority | F1: Size | G1: Assignee Role | H1: Status | I1: Blocked | J1: Description/Problem Statement | K1: Acceptance Criteria | L1: Dependencies | M1: Notes/Rationale
A2: SIM-118 | B2: Create performance benchmark harness — without measurement, SLA targets are estimates | C2: Performance | D2: Gap | E2: P1 | F2: M (3–5 days) | G2: Performance Engineer | H2: Closed | I2: No | J2: No benchmarking infrastructure exists. All performance estimates from the PE audit are models derived from known Python/FAISS throughput, not measurements on this codebase. The benchmark harness must exist before Phase 4 simulation loop code is written, or performance regressions accumulate invisibly. | K2: 1. Create tests/performance/bench_simulation.py with pytest-benchmark fixtures. 2. Benchmark 1 — Engine query latency: pitcher engine query() p50 <= 5ms, p99 <= 20ms. 3. Benchmark 2 — Arsenal cache lookup: all scores for one query pitcher from 2,400-profile cache <= 0.1ms (validates SIM-075 NumPy slice). 4. Benchmark 3 — GMM fitting: all pitchers for one season <= 10 minutes on CI machine. 5. Benchmark 4 (Phase 4 stub): simulate_game() median <= 2s — add with pytest.mark.skip until Phase 4 exists. 6. Benchmark 5 (Phase 5 stub): run_simulations(n=100) <= 30s — same skip pattern. 7. Add to CI as weekly scheduled job (not per-commit). | L2: SIM-075 (must be benchmarked after vectorization), SIM-147 (pytest config) | M2: All PE recommendations are hypothetical until this exists. Build it now, validate Phase 4 later.
A3: SIM-128 | B3: Redesign override panel as staged-change queue with undo, multi-change, visual indicator system | C3: Frontend | D3: Improvement | E3: P1 | F3: L (1–2 weeks) | G3: UX Designer | H3: Open | I3: No | J3: The current override spec supports only one substitution at a time with no undo. Real managerial decisions involve multiple simultaneous changes. The visual indicator for override mode is required but not designed. This is the most complex UI component in the entire platform. | K3: 1. Staging area: queue of pending changes before confirmation. Each change listed with player_out → player_in + position + X button to remove. 2. Confirm All: single button submits all staged changes in one POST /simulate/with_override call. 3. Override visual indicator (four rules): (a) full-width amber banner above simulation results; (b) WinProbabilityBar, ProjectedBoxscore, ScoreDistributionChart all have amber left border; (c) page tab shows '(Override)'; (d) state persists until user clicks 'Clear override' — never auto-cleared. 4. Side-by-side comparison: WinProbabilityBar shows two stacked bars — 'Override' (amber) and 'Actual' (team color). ScoreDistributionChart shows overlapping histograms at 30% opacity. 5. Backend: POST /simulate/with_override must accept array of substitutions. | L3: SIM-109 (multi-substitution API endpoint), SIM-126 (Game Page layout — override drawer position) | M3: Most complex UI component — must be fully spec'd before Phase 6 Step 6.5 begins.
A4: SIM-111 | B4: Define play pool query API column contracts before Phase 3 delivery | C4: Backend API | D4: Gap | E4: P1 | F4: S (1–2 days) | G4: Backend Developer + Data Engineer | H4: Closed | I4: No | J4: The play pool query API (get_pitch_pool(), get_outcome_pool(), get_batted_ball_pool()) has no defined column contract. Phase 4 Steps 2 and 3b sample from DataFrames returned by these functions. Without knowing what columns exist, Phase 4 step implementations will be written against assumed schemas that break at integration time. | K4: 1. Define get_pitch_pool() → DataFrame: [pitch_id, pitcher_id, batter_id, p_throws, stand, velo, ivb, hb, spin_rate, spin_axis, release_x, release_z, release_ext, plate_x, plate_z, zone, season, game_date, recency_weight, combined_weight]. 2. Define get_outcome_pool() additions: [exit_velo, launch_angle, spray_angle, pull_relative_spray_angle, bb_type, result_hits, result_outs, result_runs, fielded_by_position, fielding_error_position]. 3. Define combined_weight computation: pitcher_similarity × batter_similarity × situation_similarity × recency_weight. 4. Formalise as TypedDict or dataclass in simulator/pool_api.py. 5. PM review and approval before Phase 3 coding begins. | L4: SIM-076 (recency_weight column must exist) | M4: Phase 4 cannot be correctly implemented without this contract being locked.
A5: SIM-107 | B5: Create tests/unit/test_live_ingestion_pipeline.py — 7 BE bugs, 0% coverage | C5: Testing | D5: Bug | E5: P1 | F5: M (3–5 days) | G5: Backend Developer + QA/DevOps | H5: Open | I5: No | J5: live_ingestion_pipeline.py has zero test coverage. The BE audit found 7 bugs in this file. All 7 would be caught by basic unit tests. The component handles live game state during MLB games — bugs manifest during production use with no test safety net. All prior BE bug fixes (SIM-099, SIM-100, SIM-101, SIM-102, SIM-103) need permanent regression coverage. | K5: 1. GameStateBuilder.build() with fixture feed dict: assert all required JSONB keys present; assert current_pitcher_id from matchup dict (not offense dict). 2. _infer_role(): parametrize SP (5.1IP), Opener (0.2IP, 10BF), MRP (1.1IP), RP. 3. _should_resimulate(): isComplete=True → True; duplicate at_bat guard → False; non-Live status → False. 4. ConnectionManager.broadcast(): dead connection cleanup; no RuntimeError when disconnect fires during send. 5. _get_days_rest() batch: 12 bullpen pitchers → exactly 1 DB query. 6. Redis key regression: key written by _cache_to_redis() == key read by fallback. 7. Hypothesis property test: random valid feed dict → always produces all required keys. 8. Use AsyncMock for all asyncpg calls; pytest.mark.asyncio. Minimum 40 tests. | L5: SIM-099, SIM-100, SIM-101, SIM-102, SIM-103 (bugs fixed first), SIM-152 (conftest) | M5: Most complex component in Phase 2 scope with zero coverage — highest testing priority.
A6: SIM-115 | B6: Prune DuckDB sim pool indexes — keep 3 query-path indexes, drop 8 write-overhead indexes | C6: Schema / ETL | D6: Improvement | E6: P1 | F6: S (< 1 day) | G6: Data Engineer + Performance Engineer | H6: Closed | I6: No | J6: sim.pitch_pool has 11 secondary indexes. DuckDB is a columnar engine with built-in zone maps and Bloom filters — it benefits far less from secondary indexes than PostgreSQL. Most of these indexes will never be used by the play pool query API which pre-filters by pitcher before any pool is materialized as a DataFrame. The 11 indexes add nightly rebuild overhead on a 1M+ row table. | K6: 1. Keep on sim.pitch_pool: idx_pp_pitcher_season (primary access pattern), idx_pp_outcome (filters in_play rows), idx_pp_count (situational pre-filter). 2. Drop: idx_pp_pitcher, idx_pp_batter, idx_pp_season, idx_pp_game_date, idx_pp_batter_season, idx_pp_runners, idx_pp_velo, idx_pp_ivb — all superseded by pitcher pre-filter reducing scan to ~3,000 rows. 3. Apply same analysis to sim.outcome_pool. 4. PE must confirm Phase 3 play pool query access patterns (SIM-111) before finalizing which indexes to keep. 5. Deliver as DuckDB migration file. | L6: SIM-111 (play pool query contracts must be confirmed first) | M6: Do not drop indexes until SIM-111 access patterns are confirmed — dropping the wrong index causes a regression.
A7: SIM-119 | B7: Define per-step time budget for the 8-step simulation loop | C7: Performance | D7: Gap | E7: P1 | F7: S (< 1 day) | G7: Performance Engineer + Backend Developer | H7: Closed | I7: No | J7: The 2s single-game SLA has no per-step budget. Without step budgets, Phase 4 has no way to know if each step is on track during implementation. Each step must have a pytest-benchmark assertion as part of its acceptance criteria. | K7: 1. Lock step budgets (per pitch invocation): Step 1 steal ≤0.05ms · Step 2 pitch selection ≤0.15ms · Step 3a/3b outcome ≤0.15ms · Step 4 fielding ≤0.10ms · Step 5 baserunner ≤0.05ms · Step 6 state update ≤0.05ms · Step 7 manager (end of PA only) ≤0.20ms · Step 8 loop control ≤0.03ms. 2. Total per pitch: ≤0.78ms × 300 pitches = ≤234ms per game iteration → 100 iterations in ≤23.4s (within 30s SLA). 3. Each step implementation in simulator/steps/ must include a pytest-benchmark assertion against its budget. 4. Add benchmarks to the SIM-118 harness as Benchmark Group 3 (simulation step budgets). | L7: SIM-118 (benchmark harness infrastructure) | M7: Step budgets convert the 30s SLA from a post-hoc check into a per-step implementation requirement.
A8: SIM-120 | B8: Benchmark ProcessPoolExecutor vs ThreadPoolExecutor for simulation runner before Phase 5 commits | C8: Performance | D8: Gap | E8: P1 | F8: S (1–2 days) | G8: Performance Engineer + Backend Developer | H8: Open | I8: No | J8: The ProcessPoolExecutor choice is based on the assumption that Python's GIL bottlenecks thread-parallel simulation. FAISS and NumPy both release the GIL during computation. ThreadPoolExecutor may achieve comparable throughput with zero IPC overhead, zero spawn cost, and shared memory automatically. This must be benchmarked on one complete game simulation before Phase 5 commits to an architecture. | K8: 1. Requires Phase 4 simulate_game() to exist before benchmarking. 2. Benchmark ProcessPoolExecutor (n=100): shared memory for play pool and FAISS index, measure throughput and total RAM. 3. Benchmark ThreadPoolExecutor (n=100): threads share heap automatically, no shared memory setup, measure throughput and CPU utilization across cores. 4. Decision rule: if ThreadPoolExecutor achieves >= 80% of ProcessPoolExecutor throughput, prefer threads for operational simplicity. 5. Document benchmark results and architectural decision in simulator/runner.py. | L8: Phase 4 simulate_game() must be implemented first | M8: If threads work, eliminates the entire shared memory complexity of the process pool approach.
A9: SIM-113 | B9: Fix GMM batch pipeline performance: dynamic n_workers, eliminate per-pitcher IPC, batch DuckDB writes | C9: Performance | D9: Improvement | E9: P1 | F9: M (3–5 days) | G9: Performance Engineer + Data Engineer | H9: Closed | I9: No | J9: Three performance bugs in player_profile_computor.py GMM fitting: (1) n_workers hardcoded to 8 — over-subscribes 4-core machines. (2) Per-pitcher IPC overhead: one DataFrame per pitcher sent to workers via pickle (~34s of overhead on a 4-season rebuild). (3) Per-GMM DuckDB UPDATEs: ~2,800 sequential writes after fitting. (4) O(N×P) pandas split: season_df filtered per pitcher in a loop. | K9: 1. Restore dynamic worker count: n_workers = max(1, (os.cpu_count() or 2) - 1). 2. Eliminate per-pitcher IPC: pass full season NumPy array + pitcher_id_list to workers; worker splits internally; one round-trip per chunk. 3. Replace per-pitcher UPDATEs with bulk INSERT OR REPLACE using parameterized DuckDB execute (not f-string SQL). 4. Replace per-pitcher pandas filter loop with single season_df.groupby('pitcher_id') call. 5. Benchmark: 4-season full rebuild completes GMM fitting + writing in <= 30 minutes. | L9: None | M9: Makes the nightly batch job tractable before it's run against real multi-season data.
